Workbook

Sheet Sheet说明
B1: Sheet名 | C1: 说明
B2: BespokeSkill | C2: 基于Luban特性，可以让两个Sheet来合并称为1张数据表，即两个Sheet的表头项目必须相同，但顺序可以不同。因此可以将每个Sheet各自关心的列放在前面。
C3: Skill和BespokeSkill是同一张表，但BespokeSkill属于是定制化的特殊技能不需要通过原子参数配置，因此分成两个Sheet来管理。
C4: 待游戏后期，在BespokeSkill中发现多个技能实际结构差不多时，再将他们提炼成原子，迁移到Skill中。
B5: 枚举 | C5: 不导出，只为策划编辑Excel时可以提供一个方便的下拉菜单而存在。
B6: Card 头脑风暴备份 | C6: 过时信息，先不删，但不要以里面的内容为准。

Sheet PlayerCard
A1: ##var | B1: id | C1: name | D1: factionTag | E1: cardTypeTag | F1: raceTag | G1: power | H1: manpower | I1: manpowerCost | J1: maxDuration | K1: basePrice | N1: *abilityList | R1: assetId
A2: ##type | B2: int | C2: string | D2: Tags.FactionTag | E2: Tags.CardTypeTag | F2: Tags.RaceTag | G2: int | H2: int | I2: int | J2: int | K2: int | N2: list,CardSkill.Ability | R2: int
A3: ## | E3: 虽然在游戏中都会被包装成角色生物，但内部实现机制实际上还是区分了生物和法术等,目的是将来这套程序在开发别的游戏项目时可以复用。 | I3: 在野区需要派遣多少人力可以获得该卡牌 | J3: 光环、英雄、陷阱等支援区卡牌专用 | K3: 卡牌出现在商店中时，所需金币基础价格，MVP版本不考虑平衡。 | L3: 设计阶段用于快速记录想法，游戏内无作用 | M3: 设计阶段用于快速记录想法，游戏内无作用
A4: ##var | N4: abilityTriggerTag | O4: skillId | P4: isOnce
A5: ## | N5: 触发时机标签 | O5: 技能id | P5: 是绝响
A6: ## | B6: id | C6: 卡牌名称 | D6: 派系 | E6: 卡牌类型 | F6: 卡牌族类 | G6: 战力 | H6: 人力 | I6: 所需人力 | J6: 持续回合 | K6: 价格 | L6: 配方想法 | M6: 技能想法 | N6: 卡牌能力列表 | Q6: 备注 | R6: 卡面美术资源
B7: 1001 | C7: 民兵 | D7: 灰沙 | E7: 生物 | F7: 普通 | G7: 1 | H7: 0 | I7: 1 | K7: 100 | R7: 1001
B8: 1002 | C8: 学徒 | D8: 灰沙 | E8: 生物 | F8: 普通 | G8: 0 | H8: 1 | I8: 1 | K8: 100 | R8: 1002
B9: 1003 | C9: 余火士兵 | D9: 红焰 | E9: 生物 | F9: 普通 | G9: 2 | H9: 0 | I9: 2 | K9: 100 | R9: 1003
B10: 1004 | C10: 余火学者 | D10: 红焰 | E10: 生物 | F10: 普通 | G10: 0 | H10: 2 | I10: 3 | K10: 100 | R10: 1004
B11: 1005 | C11: 马匹 | D11: 绿箭 | E11: 生物 | F11: 普通 | G11: 0 | H11: 3 | I11: 3 | K11: 100 | R11: 1005
B12: 1006 | C12: 余火骑兵 | D12: 绿箭 | E12: 生物 | F12: 普通 | G12: 5 | H12: 0 | I12: 6 | K12: 100 | L12: 士兵+马匹=骑兵 | R12: 1006
B13: 1007 | C13: 余火信骑 | D13: 蓝霜 | E13: 生物 | F13: 普通 | G13: 0 | H13: 2 | I13: 7 | K13: 100 | L13: 学者+马匹=传信骑兵 | M13: 进场后，摸1张牌 | N13: 进场 | O13: 1001 | R13: 1007
B14: 1008 | C14: 马贩子 | D14: 蓝霜 | E14: 法术 | F14: 普通 | G14: 0 | H14: 1 | I14: 6 | K14: 100 | M14: 进场后，召唤2张马匹卡到校场区 | N14: 进场 | O14: 1002 | P14: TRUE | Q14: 这些马都是“自愿”的 | R14: 1008
B15: 1009 | C15: 灰眼导师 | D15: 红焰 | E15: 生物 | F15: 普通 | G15: 2 | H15: 0 | I15: 4 | K15: 100 | Q15: “雾都的人都疯了？我可没疯，我本来就什么都看不清。但奇怪的是在雾里，我反而能看见一些东西。” | R15: 1009
B16: 1010 | C16: 剑士 | D16: 红焰 | E16: 生物 | F16: 普通 | G16: 5 | H16: 0 | I16: 5 | K16: 100 | L16: 灰眼导师+士兵=灰眼导师+剑士 | R16: 1010
B17: 1011 | C17: 流浪剑客 | D17: 灰沙 | E17: 生物 | F17: 普通 | G17: 7 | H17: 0 | I17: 5 | K17: 100 | Q17: “我……是……谁……” | R17: 1011
A18: line
B19: 1012 | C19: 女酒保 | D19: 蓝霜 | E19: 法术 | F19: 普通 | G19: 0 | H19: 1 | I19: 6 | K19: 100 | M19: 进场后，摸2张牌 | N19: 进场 | O19: 10001 | P19: TRUE | Q19: 她不打架，但她知道每一个佣兵的名字，也记得谁赊了账。 | R19: 1012
B20: 1013 | C20: 狼帮摩托手 | D20: 绿箭 | E20: 生物 | F20: 普通 | G20: 7 | H20: 0 | I20: 5 | K20: 100 | M20: 进场后，弃掉最左边的1张手牌 | N20: 进场 | O20: 1004 | Q20: 群狼帮的车手从不刹车，当然，他们也从不检查后座的妞还在不在。 | R20: 1013
B21: 1014 | C21: 银镰狙击手 | D21: 蓝霜 | E21: 生物 | F21: 普通 | G21: 0 | H21: 0 | I21: 4 | K21: 100 | M21: 进场后，选择1名战力5以下的敌人，将其直接击败 | N21: 进场 | O21: 10002 | Q21: “银焰帮的规矩只有一条：开一枪，换一个地方。群狼帮的人直到倒下都没看清子弹从哪来。” | R21: 1014
B22: 1015 | C22: 小镇作家 | D22: 蓝霜 | E22: 法术 | F22: 普通 | G22: 0 | H22: 1 | I22: 4 | K22: 100 | M22: 进场后，弃掉最左边的1张手牌。摸1张牌 | N22: 进场 | O22: 3003 | P22: TRUE | R22: 1015
B23: 1016 | C23: 失控的答录机 | D23: 蓝霜 | E23: 生物 | F23: 智械 | G23: 2 | H23: 0 | I23: 4 | K23: 100 | M23: 进场后，摸1张牌，然后弃掉最左边的手牌 | N23: 进场 | O23: 3004 | R23: 1016
B24: 1017 | C24: 悲剧作家 | D24: 绿箭 | E24: 生物 | F24: 普通 | G24: 0 | H24: 4 | I24: 5 | K24: 100 | L24: 小镇作家+女酒保=悲剧作家 | M24: 进场后，从牌库中将2张牌置入弃牌区 | N24: 进场 | O24: 1005 | Q24: 有人问他为什么只写悲剧。他抿了一口酒：“喜剧……需要两个人。” | R24: 1017
B25: 1018 | C25: 头号通缉犯 | D25: 灰沙 | E25: 生物 | F25: 猎人 | G25: 7 | H25: 0 | I25: 5 | K25: 100 | M25: 进场后，在野区末尾添加1名随机敌人 | N25: 进场 | O25: 2002 | Q25: 高塔覆灭二十年了，安保机器人还在追他。是系统错误？漏洞？还是……它根本没收到“下班”的通知？ | R25: 1018
B26: 1019 | C26: 捡零件的矮人 | D26: 绿箭 | E26: 生物 | F26: 矮人 | G26: 3 | H26: 0 | I26: 7 | K26: 100 | M26: 进场后，从弃牌区随机回收1张具有绝响的卡牌 | N26: 进场 | O26: 1011 | R26: 1019
B27: 1020 | C27: 滑翔翼佣兵 | D27: 红焰 | E27: 生物 | F27: 亚人 | G27: 4 | H27: 0 | I27: 7 | K27: 100 | M27: 进场后，从战利品区随机打捞1张卡牌，并将其置入手牌 | N27: 进场 | O27: 1006 | Q27: "这回发了！回去就把滑翔翼都换成纯金的！" | R27: 1020
B28: 1021 | C28: 联邦征兵官 | D28: 红焰 | E28: 生物 | F28: 普通 | G28: 4 | H28: 0 | I28: 7 | K28: 100 | M28: 离场后，随机将战利品区的1张牌置入牌库顶 | N28: 离场 | O28: 1007 | Q28: "来不及解释了，快上车！" | R28: 1021
B29: 1022 | C29: 调酒师 | D29: 绿箭 | E29: 生物 | F29: 普通 | G29: 0 | H29: 1 | I29: 6 | K29: 100 | M29: 进场后，摸1张牌，然后选择1张手牌将其置入虚空区 | N29: 进场 | O29: 3002 | P29: TRUE | Q29: 喝了这杯，忘掉那些伤心事吧。 | R29: 1022
B30: 1023 | C30: 冰结法师 | D30: 蓝霜 | E30: 生物 | F30: 普通 | G30: 3 | H30: 0 | I30: 6 | K30: 100 | M30: 进场后，你可以选择1名敌人将其置入野区末位。 | N30: 进场 | O30: 2001 | R30: 1023
B31: 1024 | C31: 鉴定师 | D31: 蓝霜 | E31: 生物 | F31: 普通 | G31: 0 | H31: 1 | I31: 3 | K31: 100 | M31: 进场后，摸2张牌，然后弃掉其中1张牌 | N31: 进场 | O31: 4001 | Q31: 在驿镇，没人敢卖假货给王罡。不是因为怕他识破，而是怕他识破后那一锤子的动静 | R31: 1024
B32: 1025 | C32: 倒吊人 | D32: 灰沙 | E32: 生物 | F32: 普通 | G32: 0 | H32: 0 | I32: 6 | K32: 100 | M32: 进场后，选择校场上1张孤牌将其置入弃牌区，若此做摸1张牌 | N32: 进场 | O32: 3001 | Q32: 他说这是献祭仪式。但有时候，祭品就是他自己。 | R32: 1025
B33: 1026 | C33: 鼠人飞刀手 | D33: 蓝霜 | E33: 生物 | F33: 亚人 | G33: 0 | H33: 0 | I33: 2 | K33: 100 | M33: 进场后，随机击败1名战力3以下的敌人 | N33: 进场 | O33: 1003 | Q33: "鼠鼠我呀……" | R33: 1026
B34: 1027 | C34: 募捐使者 | D34: 灰沙 | E34: 生物 | F34: 普通 | G34: 0 | H34: 0 | I34: 4 | K34: 100 | M34: 进场后，获得5X金币，X为校场中的生物数量 | N34: 进场 | O34: 20001 | Q34: "天呐，这地方人真多……" | R34: 1027
B35: 1028 | C35: 学院监考官 | D35: 蓝霜 | E35: 生物 | F35: 改造者 | G35: 0 | H35: 2 | I35: 5 | K35: 100 | M35: 进场后，抽2张牌，留下其中的蓝霜牌，弃掉其余牌 | N35: 进场 | O35: 4002 | Q35: 失格者不配拥有知识——他连看都不配看。 | R35: 1028
B36: 1029 | C36: 砍价高手 | D36: 紫雾 | E36: 光环 | F36: 亚人 | G36: 0 | H36: 2 | I36: 4 | J36: 2 | K36: 100 | M36: 在场时，野区所有中立牌人力费用减1 | N36: 在场 | O36: 20002 | Q36: "不降价？那我就砍一刀。" | R36: 1029
B37: 1030 | C37: 绿洲大亨 | D37: 红焰 | E37: 生物 | F37: 亚人 | G37: 0 | H37: 2 | I37: 5 | K37: 100 | M37: 进场时，将1张劳工添加至手牌 | N37: 进场 | O37: 10003 | Q37: "签了这份合同，这个人就是你的啦——可不许反悔哟。" | R37: 1030
B38: 1031 | C38: 劳工 | D38: 灰沙 | E38: 生物 | F38: 亚人 | G38: 1 | H38: 0 | I38: 1 | K38: 100 | Q38: "我自由了……吗？" | R38: 1031
B39: 9001 | C39: 作弊民兵 | D39: 灰沙 | E39: 生物 | F39: 普通 | G39: 99 | H39: 0 | I39: 1 | K39: 100 | R39: 1001
B40: 9002 | C40: 作弊学徒 | D40: 灰沙 | E40: 生物 | F40: 普通 | G40: 0 | H40: 99 | I40: 1 | K40: 100 | R40: 1002
...

Sheet Card 头脑风暴备份
B1: id | C1: name | D1: faction | E1: cardType | F1: cardRace | G1: power | H1: manpower | I1: manpowerCost | J1: basePrice | L1: cardTriggerTagList | N1: skillIdList | P1: assetId
B2: int | C2: string | D2: CardFaction | E2: CardType | F2: CardRace | G2: int | H2: int | I2: int | J2: int | L2: (list#sep=|),CardTriggerTag | N2: (list#sep=|),int | P2: int
E3: 虽然在游戏中都会被包装成角色生物，但内部实现机制实际上还是区分了生物和法术等,目的是将来这套程序在开发别的游戏项目时可以复用。 | I3: 在野区需要派遣多少人力可以获得该卡牌 | J3: 卡牌出现在商店中时，所需金币基础价格，MVP版本不考虑平衡。 | K3: 设计阶段用于快速记录想法，游戏内无作用 | M3: 设计阶段用于快速记录想法，游戏内无作用
A4: ## | B4: id | C4: 卡牌名称 | D4: 派系 | E4: 卡牌类型 | F4: 卡牌族类 | G4: 战力 | H4: 人力 | I4: 所需人力 | J4: 价格 | K4: 配方想法 | L4: 被动标签 | M4: 技能想法 | N4: 技能id组 | O4: 备注 | P4: 卡面美术资源
B5: 1001 | C5: 民兵 | D5: 灰沙 | E5: 生物 | F5: 普通 | G5: 1 | H5: 0 | I5: 1 | J5: 100
B6: 1002 | C6: 学徒 | D6: 灰沙 | E6: 生物 | F6: 普通 | G6: 0 | H6: 1 | I6: 1 | J6: 100
B7: 1003 | C7: 士兵 | D7: 红焰 | E7: 生物 | F7: 普通 | G7: 2 | H7: 0 | I7: 2 | J7: 100
B8: 1004 | C8: 学者 | D8: 红焰 | E8: 生物 | F8: 普通 | G8: 0 | H8: 2 | I8: 3 | J8: 100
B9: 1005 | C9: 马匹 | D9: 绿箭 | E9: 生物 | F9: 普通 | G9: 0 | H9: 3 | I9: 3 | J9: 100
B10: 1006 | C10: 骑兵 | D10: 绿箭 | E10: 生物 | F10: 普通 | G10: 5 | H10: 0 | I10: 6 | J10: 100 | K10: 士兵+马匹=骑兵
B11: 1007 | C11: 传信骑兵 | D11: 蓝霜 | E11: 生物 | F11: 普通 | G11: 0 | H11: 2 | I11: 7 | J11: 100 | K11: 学者+马匹=传信骑兵 | L11: 进场 | M11: 进场后，摸1张牌
B12: 1008 | C12: 马贩子 | D12: 蓝霜 | E12: 法术 | F12: 普通 | G12: 0 | H12: 1 | I12: 6 | J12: 100 | L12: 绝响 | M12: 进场后，召唤2张马匹卡到校场区 | O12: 这些马都是“自愿”的
B13: 1009 | C13: 灰眼导师 | D13: 红焰 | E13: 生物 | F13: 普通 | G13: 2 | H13: 0 | I13: 4 | J13: 100 | O13: “雾都的人都疯了？我可没疯，我本来就什么都看不清。但奇怪的是在雾里，我反而能看见一些东西。”
B14: 1010 | C14: 剑士 | D14: 红焰 | E14: 生物 | F14: 普通 | G14: 5 | H14: 0 | I14: 5 | J14: 100 | K14: 灰眼导师+士兵=灰眼导师+剑士
B15: 1011 | C15: 流浪剑客 | D15: 灰沙 | E15: 生物 | F15: 普通 | G15: 7 | H15: 0 | I15: 5 | J15: 100 | O15: “我……是……谁……”
B16: 1012 | C16: 女酒保 | D16: 蓝霜 | E16: 法术 | F16: 普通 | G16: 0 | H16: 1 | I16: 6 | J16: 100 | L16: 绝响|进场 | M16: 进场后，摸2张牌 | O16: 她不打架，但她知道每一个佣兵的名字，也记得谁赊了账。
B17: 1013 | C17: 狼帮摩托手 | D17: 绿箭 | E17: 生物 | F17: 普通 | G17: 7 | H17: 0 | I17: 5 | J17: 100 | L17: 进场 | M17: 进场后，随机弃掉1张手牌 | O17: 群狼帮的车手从不刹车，当然，他们也从不检查后座的妞还在不在。
B18: 1014 | C18: 银镰狙击手 | D18: 蓝霜 | E18: 生物 | F18: 普通 | G18: 0 | H18: 0 | I18: 4 | J18: 100 | L18: 进场 | M18: 进场后，选择1名战力5以下的敌人，将其直接击败 | O18: “银焰帮的规矩只有一条：开一枪，换一个地方。群狼帮的人直到倒下都没看清子弹从哪来。”
B19: 1015 | C19: 小镇作家 | D19: 蓝霜 | E19: 法术 | F19: 普通 | G19: 0 | H19: 1 | I19: 4 | J19: 100 | L19: 绝响|进场 | M19: 进场后，弃掉最左边的手牌，若此做摸1张牌
B20: 1016 | C20: 失控的答录机 | D20: 蓝霜 | E20: 生物 | F20: 智械 | G20: 2 | H20: 0 | I20: 4 | J20: 100 | L20: 进场 | M20: 进场后，摸1张牌，然后弃掉最左边的手牌
B21: 1017 | C21: 悲剧作家 | D21: 绿箭 | E21: 生物 | F21: 普通 | G21: 0 | H21: 4 | I21: 5 | J21: 100 | K21: 小镇作家+女酒保=悲剧作家 | L21: 进场 | M21: 进场后，从牌库中将2张牌置入弃牌区 | O21: 有人问他为什么只写悲剧。他抿了一口酒：“喜剧……需要两个人。”
B22: 1018 | C22: 头号通缉犯 | D22: 灰沙 | E22: 生物 | F22: 猎人 | G22: 7 | H22: 0 | I22: 5 | J22: 100 | L22: 进场 | M22: 进场后，在野区末尾添加一名随机敌人 | O22: 高塔覆灭二十年了，安保机器人还在追他。是系统错误？漏洞？还是……它根本没收到“下班”的通知？
B23: 1019 | C23: 捡零件的矮人 | D23: 绿箭 | E23: 生物 | F23: 猎人 | G23: 3 | H23: 0 | I23: 7 | J23: 100 | L23: 进场|回收 | M23: 进场后，从弃牌区随机回收一张具有绝响的卡牌，并将其置入手牌
B24: 1020 | C24: 滑翔翼佣兵 | D24: 红焰 | E24: 生物 | F24: 亚人 | G24: 4 | H24: 0 | I24: 7 | J24: 100 | L24: 进场|打捞 | M24: 进场后，从战利品区随机打捞一张卡牌，并将其置入手牌 | O24: “这回发了！回去就把滑翔翼都换成纯金的！”
B25: 1021 | C25: 联邦征兵官 | D25: 红焰 | E25: 生物 | F25: 普通 | G25: 4 | H25: 0 | I25: 7 | J25: 100 | L25: 离场 | M25: 离场后，随机将战利品区的一张牌置入牌库顶 | O25: "来不及解释了，快上车！"
B26: 1022 | C26: 调酒师 | D26: 绿箭 | E26: 生物 | F26: 普通 | G26: 0 | H26: 1 | I26: 6 | J26: 100 | L26: 绝响|进场 | M26: 进场后，摸1张牌，然后选择一张手牌将其置入虚空区 | O26: 喝了这杯，忘掉那些伤心事吧。
B27: 1023 | C27: 冰结法师 | D27: 蓝霜 | E27: 生物 | F27: 普通 | G27: 3 | H27: 0 | I27: 6 | J27: 100 | L27: 先机 | M27: 先机，与敌人交战前触发，将敌人置入野区末位，然后结束本次交战
B28: 1024 | C28: 鉴定师 | D28: 蓝霜 | E28: 生物 | F28: 普通 | G28: 0 | H28: 1 | I28: 3 | J28: 100 | L28: 进场 | M28: 进场后，摸2张牌，然后弃掉其中1张牌 | O28: 在驿镇，没人敢卖假货给王罡。不是因为怕他识破，而是怕他识破后那一锤子的动静
B29: 1025 | C29: 倒吊人 | D29: 灰沙 | E29: 生物 | F29: 普通 | G29: 0 | H29: 0 | I29: 6 | J29: 100 | L29: 进场 | M29: 进场后，选择校场上1张孤牌将其置入弃牌区，若此做摸1张牌 | O29: 他说这是献祭仪式。但有时候，祭品就是他自己。
B30: 1026 | C30: 鼠人飞刀手 | D30: 蓝霜 | E30: 生物 | F30: 亚人 | G30: 0 | H30: 0 | I30: 2 | J30: 100 | L30: 进场 | M30: 进场后，随机击败1名战力3以下的敌人 | O30: “鼠鼠我呀……”
B31: 1027 | C31: 募捐使者 | D31: 灰沙 | E31: 生物 | F31: 普通 | G31: 0 | H31: 0 | I31: 4 | J31: 100 | L31: 进场 | M31: 进场后，获得5X金币，X为校场中的生物数量 | O31: “天呐，这地方人真多……”
B32: 1028 | C32: 学院监考官 | D32: 蓝霜 | E32: 生物 | F32: 改造者 | G32: 0 | H32: 2 | I32: 5 | J32: 100 | L32: 进场 | M32: 进场后，抽两张牌，留下其中的蓝霜牌，弃掉其余牌 | O32: 失格者不配拥有知识——他连看都不配看。
B33: 1029 | C33: 砍价高手 | D33: 紫雾 | E33: 光环 | F33: 亚人 | G33: 0 | H33: 2 | I33: 4 | J33: 100 | L33: 在场 | M33: 在场时，野区所有资源牌人力费用减1 | O33: “不降价？那我就砍一刀。”
B34: 1030 | C34: 绿洲大亨 | D34: 红焰 | E34: 生物 | F34: 亚人 | G34: 0 | H34: 2 | I34: 5 | J34: 100 | L34: 进场 | M34: 进场时，将1张劳工添加至手牌 | O34: “签了这份合同，这个人就是你的啦——可不许反悔哟。”
B35: 1031 | C35: 劳工 | D35: 灰沙 | E35: 生物 | F35: 亚人 | G35: 1 | H35: 0 | I35: 1 | J35: 100 | O35: “我自由了……吗？”

Sheet Recipe
A1: ##var | B1: id | C1: ingredientIdList | F1: productIdList | I1: #comment
A2: ##type | B2: int | C2: list,int | F2: list,int
A3: ## | C3: i1 | D3: i2 | E3: i3 | F3: p1 | G3: p2 | H3: p3 | I3: 游戏中玩家看不到，展示时也是按照规则用美术资源拼出来的公式
A4: ## | B4: 配方ID | C4: 原料列表 | F4: 产物列表 | I4: 配方备注
B5: 1001 | C5: 1003 | D5: 1005 | F5: 1006 | I5: 士兵+马匹=骑兵
B6: 1002 | C6: 1004 | D6: 1005 | F6: 1007 | I6: 学者+马匹=传信骑兵
B7: 1003 | C7: 1012 | D7: 1015 | F7: 1017 | I7: 女酒保+小镇作家=悲剧作家
B8: 1004 | C8: 1009 | D8: 1003 | F8: 1009 | G8: 1010 | I8: 灰眼导师+士兵=灰眼导师+剑士

Sheet PlayerClassDeck
A1: ##var | B1: playerClassId | C1: name | D1: description | E1: revealLevel | F1: unlockGold | G1: *startingDeck | H1: #Lookup函数校验
A2: ##type | B2: int | C2: string | D2: string | E2: int | F2: int | G2: list,int
A3: ## | B3: 职业ID | C3: 职业名称 | D3: 职业描述 | E3: 揭示所需等级 | F3: 解锁所需金币 | G3: 卡牌ID | H3: 卡牌备注
B4: 1001 | C4: 余火青年 | D4: 余火会中年轻有为的新人。起始牌组均衡，适合新手了解游戏机制。 | E4: 0 | F4: 0 | G4: 1001 | H4: =LOOKUP(G4,PlayerCard!B:B,PlayerCard!C:C) -> 民兵
G5: 1001 | H5: =LOOKUP(G5,PlayerCard!B:B,PlayerCard!C:C) -> 民兵
G6: 1001 | H6: =LOOKUP(G6,PlayerCard!B:B,PlayerCard!C:C) -> 民兵
G7: 1001 | H7: =LOOKUP(G7,PlayerCard!B:B,PlayerCard!C:C) -> 民兵
G8: 1001 | H8: =LOOKUP(G8,PlayerCard!B:B,PlayerCard!C:C) -> 民兵
G9: 1002 | H9: =LOOKUP(G9,PlayerCard!B:B,PlayerCard!C:C) -> 学徒
G10: 1002 | H10: =LOOKUP(G10,PlayerCard!B:B,PlayerCard!C:C) -> 学徒
G11: 1002 | H11: =LOOKUP(G11,PlayerCard!B:B,PlayerCard!C:C) -> 学徒
G12: 1002 | H12: =LOOKUP(G12,PlayerCard!B:B,PlayerCard!C:C) -> 学徒
G13: 1002 | H13: =LOOKUP(G13,PlayerCard!B:B,PlayerCard!C:C) -> 学徒
B14: 1002 | C14: 余火勇士 | D14: 余火会中……侧重战力。 | E14: 1 | F14: 100 | G14: 1003 | H14: =LOOKUP(G14,PlayerCard!B:B,PlayerCard!C:C) -> 余火士兵
G15: 1001 | H15: =LOOKUP(G15,PlayerCard!B:B,PlayerCard!C:C) -> 民兵
G16: 1001 | H16: =LOOKUP(G16,PlayerCard!B:B,PlayerCard!C:C) -> 民兵
G17: 1001 | H17: =LOOKUP(G17,PlayerCard!B:B,PlayerCard!C:C) -> 民兵
G18: 1001 | H18: =LOOKUP(G18,PlayerCard!B:B,PlayerCard!C:C) -> 民兵
G19: 1001 | H19: =LOOKUP(G19,PlayerCard!B:B,PlayerCard!C:C) -> 民兵
G20: 1005 | H20: =LOOKUP(G20,PlayerCard!B:B,PlayerCard!C:C) -> 马匹
G21: 1002 | H21: =LOOKUP(G21,PlayerCard!B:B,PlayerCard!C:C) -> 学徒
G22: 1002 | H22: =LOOKUP(G22,PlayerCard!B:B,PlayerCard!C:C) -> 学徒
G23: 1002 | H23: =LOOKUP(G23,PlayerCard!B:B,PlayerCard!C:C) -> 学徒
B24: 1003 | C24: 余火先知 | D24: 余火会中……侧重人力。 | E24: 2 | F24: 100 | G24: 1001 | H24: =LOOKUP(G24,PlayerCard!B:B,PlayerCard!C:C) -> 民兵
G25: 1001 | H25: =LOOKUP(G25,PlayerCard!B:B,PlayerCard!C:C) -> 民兵
G26: 1001 | H26: =LOOKUP(G26,PlayerCard!B:B,PlayerCard!C:C) -> 民兵
G27: 1001 | H27: =LOOKUP(G27,PlayerCard!B:B,PlayerCard!C:C) -> 民兵
G28: 1001 | H28: =LOOKUP(G28,PlayerCard!B:B,PlayerCard!C:C) -> 民兵
G29: 1004 | H29: =LOOKUP(G29,PlayerCard!B:B,PlayerCard!C:C) -> 余火学者
G30: 1004 | H30: =LOOKUP(G30,PlayerCard!B:B,PlayerCard!C:C) -> 余火学者
G31: 1002 | H31: =LOOKUP(G31,PlayerCard!B:B,PlayerCard!C:C) -> 学徒
G32: 1002 | H32: =LOOKUP(G32,PlayerCard!B:B,PlayerCard!C:C) -> 学徒
G33: 1002 | H33: =LOOKUP(G33,PlayerCard!B:B,PlayerCard!C:C) -> 学徒
B34: 9001 | C34: 余火程序员 | D34: 余火会的程序员，用于测试游戏，起始卡组可以根据实际需求配置任意内容 | E34: 0 | F34: 0 | G34: 1022 | H34: =LOOKUP(G34,PlayerCard!B:B,PlayerCard!C:C) -> 调酒师
G35: 9001 | H35: =LOOKUP(G35,PlayerCard!B:B,PlayerCard!C:C) -> 作弊民兵
G36: 9001 | H36: =LOOKUP(G36,PlayerCard!B:B,PlayerCard!C:C) -> 作弊民兵
G37: 9001 | H37: =LOOKUP(G37,PlayerCard!B:B,PlayerCard!C:C) -> 作弊民兵
G38: 9001 | H38: =LOOKUP(G38,PlayerCard!B:B,PlayerCard!C:C) -> 作弊民兵
G39: 1022 | H39: =LOOKUP(G39,PlayerCard!B:B,PlayerCard!C:C) -> 调酒师
G40: 9003 | H40: =LOOKUP(G40,PlayerCard!B:B,PlayerCard!C:C) -> 作弊放逐
...

Sheet 枚举
C1: 影响美术外观
A2: 卡牌全标签 | C2: 卡牌派系 | E2: 技能触发时机 | G2: 卡牌类型 | I2: 卡牌种族 | K2: 敌方队列位置 | M2: 卡牌技能效果约束模式 | O2: 后续技能效果约束模式 | Q2: 卡牌区域 | S2: 卡牌标签种类
A3: __派系 | C3: 灰沙 | E3: 白板 | G3: 生物 | I3: 普通 | K3: 首位 | M3: 直接执行 | O3: 无 | Q3: 牌库顶 | S3: 派系
A4: 灰沙 | C4: 红焰 | E4: 进场 | G4: 法术 | I4: 亚人 | K4: 末位 | M4: 你可以 | O4: 无条件执行 | Q4: 手牌 | S4: 类型
A5: 红焰 | C5: 绿箭 | E5: 离场 | G5: 陷阱 | I5: 智械 | K5: 前移 | M5: 你必须 | O5: 当你如此做 | Q5: 校场区 | S5: 种族
A6: 绿箭 | C6: 蓝霜 | E6: 在场 | G6: 光环 | I6: 猎人 | K6: 后移 | M6: 必选其一 | O6: 若你如此做 | Q6: 弃牌区 | S6: 时机
A7: 蓝霜 | C7: 紫雾 | E7: 绝响 | G7: 英雄 | I7: 蛊虫 | M7: 尽可能 | O7: 若你无法如此做 | Q7: 旅店区 | S7: 技能
A8: 紫雾 | E8: 先机 | I8: 异魔 | Q8: 虚空区 | S8: 特殊
A9: __类型 | E9: 放逐 | I9: 改造者 | Q9: 支援区
A10: 生物 | E10: 销毁 | I10: 矮人 | Q10: 野区卡组
A11: 法术 | E11: 每当 | I11: 魔灵 | Q11: 野区
A12: 陷阱 | I12: 构造体 | Q12: 战利品区
A13: 光环 | Q13: 临时区
A14: __种族 | Q14: 牌库底
A15: 普通 | Q15: 牌库任意位置
A16: 亚人
A17: 智械
A18: 猎人
A19: 蛊虫
A20: 异魔
A21: 改造者
A22: 矮人
A23: 魔灵
A24: 构造体
A25: __时机
A26: 白板
A27: 进场
... A36: 绝响

Sheet Skill
A1: ##var | B1: id | C1: name | D1: description | E1: *actionGroupList | H1: *cardSkillEffectList | T1: bespokeFileName | U1: parameterMap | W1: bespokeHandlerKey
A2: ## | B2: 计划1开头为测试过的；2开头开始为执行策划补充技能 | C2: 玩家看不见，仅做内部沟通使用，例如控制台打印信息时。 | D2: 给玩家看的描述，能需要富文本可能需要多语言。但如实现还没想好，MVP先简单以表格内的字符直接显示给玩家。 | T2: 每个复杂技能在策划文档中都对应一个单独的md文件，用于仔细描述该技能的具体效果。 | U2: 数值参数键值对，这个float会按照需求中的约定，变为特定的具体类型。例如如果约定是bool的话，0就是false，1就是true了
A3: ##type | B3: int | C3: string | D3: string | E3: list,CardSkill.ActionGroup | H3: list,CardSkill.Effect | T3: string | U3: map,string,float | W3: string
A4: ##var | E4: $type | F4: executionMode | G4: sequencingMode | H4: $type | I4: cardIdA | J4: isRandom | K4: sourceZone | L4: amountA | M4: destinationZone | N4: amountB | O4: minPower | P4: maxPower | Q4: cardTagCategory | R4: tagValue | S4: queuePosition
A5: ## | J5: bool类型 | M5: 枚举
A6: ## | B6: 技能ID | C6: 技能名称 | D6: 技能描述 | F6: 效果约束模式 | G6: 后续效果约束模式 | H6: 效果类型 | I6: 卡牌ID | J6: 是随机模式吗 | K6: 来源区域 | L6: 数量A | M6: 去向区域 | N6: 数量B | O6: min战力以上 | P6: max战力以下 | Q6: 标签种类 | R6: 标签值 | S6: 队列位置 | T6: 技能需求文件名 | U6: 键 | V6: 值 | W6: 特殊技能标识名
B7: 1001 | C7: 摸1张牌 | E7: ActionGroup | F7: 直接执行 | G7: 无 | H7: Draw | L7: 1
B8: 1002 | C8: 召唤2张马匹 | E8: ActionGroup | F8: 直接执行 | G8: 无 | H8: Summon | I8: 1005 | K8: 临时区 | L8: 2 | M8: 校场区
B9: 1003 | C9: 随机直杀3 | E9: ActionGroup | F9: 直接执行 | G9: 无 | H9: Kill | J9: TRUE | P9: 3
B10: 1004 | C10: 随机弃1牌 | E10: ActionGroup | F10: 直接执行 | G10: 无 | H10: Discard | J10: TRUE | L10: 1
B11: 1005 | C11: 牌库弃2 | E11: ActionGroup | F11: 直接执行 | G11: 无 | H11: Mill | K11: 牌库顶 | L11: 2 | M11: 弃牌区
B12: 1006 | C12: 打捞1张随机卡牌，进手牌 | E12: ActionGroup | F12: 直接执行 | G12: 无 | H12: Salvage | J12: TRUE | K12: 战利品区 | L12: 1 | M12: 手牌
B13: 1007 | C13: 打捞1张指定卡牌，置入牌库顶 | E13: ActionGroup | F13: 直接执行 | G13: 无 | H13: Salvage | J13: FALSE | K13: 战利品区 | L13: 1 | M13: 牌库顶
B14: 1010 | C14: 放逐1张指定手牌 | E14: ActionGroup | F14: 直接执行 | G14: 无 | H14: Exile | J14: FALSE | K14: 手牌 | L14: 1 | M14: 虚空区
B15: 1011 | C15: 回收1张随机绝响卡 | E15: ActionGroup | F15: 直接执行 | G15: 无 | H15: RecoverBySpecialTag | J15: TRUE | K15: 弃牌区 | L15: 1 | M15: 手牌 | Q15: 特殊 | R15: 绝响
A16: line
B17: 2001 | C17: 你可以推1敌人末位 | E17: ActionGroup | F17: 你可以 | G17: 无 | H17: MoveEnemy | J17: FALSE | S17: 末位
B18: 2002 | C18: 添加1名随机敌人 | E18: ActionGroup | F18: 直接执行 | G18: 无 | H18: CreateEnemy | J18: TRUE | L18: 1 | S18: 末位
A19: line
B20: 3001 | C20: 解散校场1张孤牌，摸1 | E20: ActionGroup | F20: 直接执行 | G20: 无条件执行 | H20: FallOut | J20: FALSE | K20: 校场区 | L20: 1 | M20: 旅店区
F21: 直接执行 | G21: 无 | H21: Draw | L21: 1
B22: 3002 | C22: 摸1。必须指定1手牌放逐 | E22: ActionGroup | F22: 直接执行 | G22: 无条件执行 | H22: Draw | L22: 1
F23: 你必须 | G23: 无 | H23: Exile | J23: FALSE | K23: 手牌 | L23: 1 | M23: 虚空区
B24: 3003 | C24: 弃最左。摸1 | E24: ActionGroup | F24: 直接执行 | G24: 无条件执行 | H24: Discard | J24: TRUE | L24: 1
F25: 直接执行 | G25: 无 | H25: Draw | L25: 1
B26: 3004 | C26: 摸1。弃最左 | E26: ActionGroup | F26: 直接执行 | G26: 无条件执行 | H26: Draw | L26: 1
F27: 直接执行 | G27: 无 | H27: Discard | J27: TRUE | L27: 1
A28: line
B29: 4001 | C29: 摸2弃其中1 | E29: ActionGroup | F29: 直接执行 | G29: 无 | H29: PlayerFilter | J29: FALSE | K29: 牌库顶 | L29: 2 | M29: 弃牌区 | N29: 1
B30: 4002 | C30: 摸2弃非蓝霜 | E30: ActionGroup | F30: 直接执行 | G30: 无 | H30: FactionFilter | J30: TRUE | K30: 牌库顶 | L30: 2 | M30: 弃牌区 | N30: 99 | Q30: 派系 | R30: 蓝霜
A31: line
B32: 10001 | C32: 摸2张牌 | E32: ActionGroup | F32: 直接执行 | G32: 无 | H32: Draw | L32: 2
B33: 10002 | C33: 直杀5 | E33: ActionGroup | F33: 直接执行 | G33: 无 | H33: Kill | J33: FALSE | P33: 5
B34: 10003 | C34: 添加劳工到手牌 | E34: ActionGroup | F34: 直接执行 | G34: 无 | H34: Summon | I34: 1031 | K34: 临时区 | L34: 1 | M34: 手牌
A35: line
B36: 90001 | C36: 选择弃牌区或校场区的1张牌放逐 | E36: ActionGroup | F36: 直接执行 | G36: 无 | H36: Exile | J36: FALSE | K36: 校场区|弃牌区 | L36: 1 | M36: 虚空区

Sheet BespokeSkill
A1: ##var | B1: id | C1: name | D1: description | E1: *actionGroupList | H1: bespokeHandlerKey | I1: bespokeFileName | J1: *parameterMap | L1: *cardSkillEffectList
A2: ## | B2: 计划1开头为测试过的；2开头开始为执行策划补充技能 | C2: 玩家看不见，仅做内部沟通使用，例如控制台打印信息时。 | D2: 给玩家看的描述，能需要富文本可能需要多语言。但如何实现还没想好，MVP先简单以表格内的字符直接显示给玩家。 | I2: 每个复杂技能在策划文档中都对应一个单独的md文件，用于仔细描述该技能的具体效果。 | J2: 数值参数键值对
A3: ##type | B3: int | C3: string | D3: string | E3: list,CardSkill.ActionGroup | H3: string | I3: string | J3: map,string,float | L3: list,CardSkill.Effect
A4: ##var | E4: $type | F4: executionMode | G4: sequencingMode | L4: $type | M4: cardIdA | N4: isRandom | O4: sourceZone | P4: amountA | Q4: destinationZone | R4: amountB | S4: minPower | T4: maxPower | U4: cardTagCategory | V4: tagValue | W4: queuePosition
A5: ## | N5: bool类型 | Q5: 枚举
A6: ## | B6: 技能ID | C6: 技能名称 | D6: 技能描述 | F6: 效果约束模式 | G6: 后续效果约束模式 | H6: 特殊技能标识名 | I6: 技能需求文件名 | J6: 键 | K6: 值 | L6: 效果类型 | M6: 卡牌ID | N6: 是随机模式吗 | O6: 来源区域 | P6: 数量A | Q6: 去向区域 | R6: 数量B | S6: min战力以上 | T6: max战力以下 | U6: 标签种类 | V6: 标签值 | W6: 队列位置
B7: 20001 | C7: 产金币5倍校场 | E7: ActionGroup | F7: 直接执行 | G7: 无 | H7: GoldFromField | I7: bespoke-001.md | J7: GoldMultiplier | K7: 5 | L7: Bespoke
B8: 20002 | C8: 野区所有资源牌人力费用减1 | E8: ActionGroup | F8: 直接执行 | G8: 无 | H8: DiscountManpower | I8: bespoke-002.md | J8: ManpowerCost | K8: -1 | L8: Bespoke

Sheet Asset
A1: ##var | B1: id | D1: emoji
A2: ##type | B2: int | D2: string
A3: ## | D3: 开发阶段用emoji做卡牌图片占位符
A4: ## | B4: 资源ID | C4: 关联卡牌ID备注 | D4: Emoji占位符 | E4: 通俗名称
B5: 1001 | C5: 1001 | D5: 👨‍🌾 | E5: 持矛民兵
B6: 1002 | C6: 1002 | D6: 👨‍📖 | E6: 读书学徒
B7: 1003 | C7: 1003 | D7: 👨‍⚔️ | E7: 持剑士兵
B8: 1004 | C8: 1004 | D8: 👨‍📚 | E8: 研究学者
B9: 1005 | C9: 1005 | D9: 🐴 | E9: 马匹
B10: 1006 | C10: 1006 | D10: 🏇 | E10: 骑马战士
B11: 1007 | C11: 1007 | D11: 🏇📨 | E11: 传信骑兵
B12: 1008 | C12: 1008 | D12: 🐴💰 | E12: 卖马贩子
B13: 1009 | C13: 1009 | D13: 👨‍🏫 | E13: 灰眼导师
B14: 1010 | C14: 1010 | D14: 👨‍🗡️ | E14: 持剑战士
B15: 1011 | C15: 1011 | D15: 🗡🌫 | E15: 流浪剑客
B16: 1012 | C16: 1012 | D16: 🍸 | E16: 女酒保
... B35: 1031 | C35: 1031 | D35: 👷 | E35: 劳工

Sheet MvpEnemyCard
A1: ##var | B1: id | C1: name | D1: enemyType | E1: attackType | F1: power | G1: manpowerCost | H1: secondaryHealth | I1: groupId | J1: orderPoint | K1: weight | L1: rewardGoldAmount | M1: rewardType | N1: rewardCardId | O1: rewardPoolId | P1: skillId
A2: ##type | B2: int | C2: string | D2: Enemy.EnemyCardType | E2: Enemy.AttackType | F2: int | G2: int | H2: int | I2: int | J2: int | K2: int | L2: int | M2: Reward.DropType | N2: int | O2: int | P2: int
A3: ## | H3: 通常BOSS才会有的一种属性，越过战力门槛之后BOSS会进入狂暴状态，此时继续攻击它可削减邪能 | I3: 在需要添加卡牌时，同一组内的卡牌按照weight随机出1只添加到野区 | J3: 这标志着敌方出现的顺序，在MVP版本中为了减少随机复杂带来的测试问题，直接就按照1、2、3、4……的顺序出现即可
A4: ## | B4: id | C4: 卡牌名称 | D4: 敌人类型 | E4: 攻击方式 | F4: 战力 | G4: 招募人力 | H4: 邪能 | I4: 组id | J4: 序列点 | K4: 权重 | L4: 奖励金币 | M4: 奖励类型 | N4: 奖励卡牌 ID | O4: 奖励卡池 ID | P4: 技能 ID
B5: 1001 | C5: 沙漠飞虫 | D5: 怪物 | E5: 近战 | F5: 2 | G5: 0 | I5: 1001 | J5: 1 | K5: 100 | M5: 随机 | O5: 1001
B6: 1002 | C6: 边境暴徒 | D6: 怪物 | E6: 近战 | F6: 3 | G6: 0 | I6: 1002 | J6: 2 | K6: 100 | M6: 随机 | O6: 1001
B7: 1003 | C7: 边境劫匪 | D7: 怪物 | E7: 近战 | F7: 3 | G7: 0 | I7: 1002 | J7: 2 | K7: 100 | M7: 随机 | O7: 1001
B8: 1004 | C8: 矿洞守卫机甲 | D8: 怪物 | E8: 近战 | F8: 5 | G8: 0 | I8: 1004 | J8: 4 | K8: 100 | M8: 随机 | O8: 1001
B9: 1005 | C9: 边境劫匪 | D9: 怪物 | E9: 近战 | F9: 6 | G9: 0 | I9: 1005 | J9: 5 | K9: 100 | M9: 随机 | O9: 1001
B10: 1006 | C10: 沙漠毒虫 | D10: 怪物 | E10: 近战 | F10: 7 | G10: 0 | I10: 1005 | J10: 5 | K10: 100 | M10: 随机 | O10: 1001
B11: 1007 | C11: 蚀区狗虫 | D11: 怪物 | E11: 近战 | F11: 8 | G11: 0 | I11: 1007 | J11: 7 | K11: 100 | M11: 随机 | O11: 1001
B12: 1008 | C12: 大力工头 | D12: 怪物 | E12: 近战 | F12: 9 | G12: 0 | I12: 1008 | J12: 8 | K12: 100 | M12: 随机 | O12: 1001
B13: 1009 | C13: 矿洞巡逻机甲 | D13: 怪物 | E13: 近战 | F13: 10 | G13: 0 | I13: 1009 | J13: 9 | K13: 100 | M13: 随机 | O13: 1001
B14: 1010 | C14: 沙漠巨蝎 | D14: 怪物 | E14: 近战 | F14: 11 | G14: 0 | I14: 1009 | J14: 9 | K14: 100 | M14: 随机 | O14: 1001
B15: 1011 | C15: 猎镰虫 | D15: 怪物 | E15: 近战 | F15: 12 | G15: 0 | I15: 1011 | J15: 11 | K15: 100 | M15: 随机 | O15: 1001
B16: 1012 | C16: 暴走警卫机甲 | D16: 怪物 | E16: 近战 | F16: 13 | G16: 0 | I16: 1012 | J16: 12 | K16: 100 | M16: 随机 | O16: 1001
... B18: 1014 | C18: 矿洞精英守卫 | D18: 怪物 | E18: 近战 | F18: 15 | G18: 0 | I18: 1014 | J18: 14 | K18: 100 | M18: 随机 | O18: 1001
B19: 10001 | C19: 天塔监工 | D19: BOSS | E19: 近战 | F19: 16 | G19: 0 | H19: 30 | I19: 1015 | J19: 15 | K19: 100 | M19: 随机 | O19: 1001
B20: 21008 | C20: 马贩子 | D20: 中立 | E20: 无 | G20: {=LOOKUP(B20:B36,PlayerCard!B:B,PlayerCard!I:I)} -> 1 | I20: 1003 | J20: 3 | K20: 100 | M20: 固定 | N20: 1008
B21: 21009 | C21: 灰眼导师 | D21: 中立 | E21: 无 | G21: 1 | I21: 1003 | J21: 3 | K21: 100 | M21: 固定 | N21: 1009
B22: 21010 | C22: 剑士 | D22: 中立 | E22: 无 | G22: 1 | I22: 1003 | J22: 3 | K22: 100 | M22: 固定 | N22: 1010
B23: 21011 | C23: 流浪剑客 | D23: 中立 | E23: 无 | G23: 1 | I23: 1003 | J23: 3 | K23: 100 | M23: 固定 | N23: 1011
B24: 21012 | C24: 女酒保 | D24: 中立 | E24: 无 | G24: 1 | I24: 1003 | J24: 3 | K24: 100 | M24: 固定 | N24: 1012
B25: 21013 | C25: 狼帮摩托手 | D25: 中立 | E25: 无 | G25: 1 | I25: 1003 | J25: 3 | K25: 100 | M25: 固定 | N25: 1013
B26: 21015 | C26: 小镇作家 | D26: 中立 | E26: 无 | G26: 1 | I26: 1006 | J26: 6 | K26: 100 | M26: 固定 | N26: 1015
B27: 21016 | C27: 失控的答录机 | D27: 中立 | E27: 无 | G27: 1 | I27: 1006 | J27: 6 | K27: 100 | M27: 固定 | N27: 1016
B28: 21017 | C28: 悲剧作家 | D28: 中立 | E28: 无 | G28: 1 | I28: 1006 | J28: 6 | K28: 100 | M28: 固定 | N28: 1017
B29: 21018 | C29: 头号通缉犯 | D29: 中立 | E29: 无 | G29: 1 | I29: 1006 | J29: 6 | K29: 100 | M29: 固定 | N29: 1018
B30: 21020 | C30: 滑翔翼佣兵 | D30: 中立 | E30: 无 | G30: 1 | I30: 1006 | J30: 6 | K30: 100 | M30: 固定 | N30: 1020
B31: 21021 | C31: 联邦征兵官 | D31: 中立 | E31: 无 | G31: 1 | I31: 1010 | J31: 10 | K31: 100 | M31: 固定 | N31: 1021
B32: 21022 | C32: 调酒师 | D32: 中立 | E32: 无 | G32: 1 | I32: 1010 | J32: 10 | K32: 100 | M32: 固定 | N32: 1022
... B36: 21030 | C36: 绿洲大亨 | D36: 中立 | E36: 无 | G36: 1 | I36: 1010 | J36: 10 | K36: 100 | M36: 固定 | N36: 1030

Sheet MvpRewardPool
A1: ##var | B1: id | C1: drawCount | D1: isRemoveOnObtained | E1: *dropCardList
A2: ##type | B2: int | C2: int | D2: bool | E2: list,Reward.DropCard
A3: ##var | E3: rewardCardId | F3: amount | G3: weight
A4: ## | C4: 在该奖池内随机拿几次奖品给玩家 | D4: 每次拿到奖励，是否把该奖励从奖池中剔除 | F4: 这项奖品发几个 | G4: 加权求和，按权重区间找到命中条目
A5: ## | B5: 奖池ID | C5: 几份奖励 | D5: 是否剔除已获得奖项 | E5: 奖励卡牌Id | F5: 数量 | G5: 权重
B6: 1001 | C6: 1 | D6: FALSE | E6: 1003 | F6: 1 | G6: 100
E7: 1004 | F7: 1 | G7: 100
B8: 1002 | C8: 1 | D8: FALSE | E8: 1005 | F8: 1 | G8: 1
E9: 1006 | F9: 1 | G9: 1
E10: 1007 | F10: 1 | G10: 1
E11: 1008 | F11: 1 | G11: 1
E12: 1009 | F12: 1 | G12: 1
E13: 1010 | F13: 1 | G13: 1
E14: 1011 | F14: 1 | G14: 1
E15: 1012 | F15: 1 | G15: 1
E16: 1013 | F16: 1 | G16: 1
E17: 1014 | F17: 1 | G17: 1
E18: 1015 | F18: 1 | G18: 1
E19: 1016 | F19: 1 | G19: 1
E20: 1017 | F20: 1 | G20: 1
... E34: 1031 | F34: 1 | G34: 1

Sheet UndercityCard
A1: ##var | B1: id | C1: name | D1: enemyType | E1: attackType | F1: power | G1: manpowerCost | I1: groupId | J1: orderPoint | K1: weight | L1: rewardGoldAmount | M1: rewardType | N1: rewardCardId | O1: rewardPoolId | P1: skillId
A2: ##type | B2: int | C2: string | D2: Enemy.EnemyCardType | E2: Enemy.AttackType | F2: int | G2: int | I2: int | J2: int | K2: int | L2: int | M2: Reward.DropType | N2: int | O2: int | P2: int
A3: ## | H3: 通常BOSS才会有的一种属性，越过战力门槛之后BOSS会进入狂暴状态，此时继续攻击它可削减邪能
A4: ## | B4: id | C4: 卡牌名称 | D4: 敌人类型 | E4: 攻击方式 | F4: 战力 | G4: 招募人力 | H4: 邪能 | I4: 组id | J4: 序列点 | K4: 权重 | L4: 奖励金币 | M4: 奖励类型 | N4: 奖励卡牌 ID | O4: 奖励卡池 ID | P4: 技能 ID
B5: 1001 | C5: 地痞 | D5: 怪物 | E5: 近战 | F5: 2 | G5: 0 | I5: 1001 | J5: 0 | K5: 100 | L5: 10 | M5: 无
B6: 21003 | C6: 余火士兵 | D6: 中立 | E6: 无 | F6: 0 | G6: 2 | I6: 1002 | J6: 0 | K6: 100 | M6: 固定 | N6: 1003
B7: 21004 | C7: 余火学者 | D7: 中立 | E7: 无 | F7: 0 | G7: 3 | I7: 1003 | J7: 0 | K7: 100 | M7: 固定 | N7: 1004

Sheet GuideRecipe
C1: hintedRecipeId | D1: hintCondition
